### Exceptions 异常

#### Error 对象

> 通过Error的构造器可以创建一个错误对象。当运行时错误产生时，Error的实例对象会被抛出。Error对象也可用于用户自定义的异常的基础对象。

```javascript

new Error('message')
```

> 当像函数一样使用 Error 时 -- 如果没有 new，它将返回一个 Error 对象。所以， 仅仅调用 Error 产生的结果与通过new 关键字构造 Error 对象生成的结果相同。 

``` javascript
  // this:
  const x = Error('I was created using a function call!');
  ​// has the same functionality as this:
  const y = new Error('I was constructed via the "new" keyword!');
```

`Error`的`Error.prototype`属性：

`Error.prototype.constructor`
实例原型的构造函数。
`Error.prototype.message`
错误信息。
`Error.prototype.name`
错误名。

以上是标准属性，还有一些根据运行时环境不同而不同的一些属性，比如Node和Chrome中的`stack`属性，包括了异常的堆栈追踪`stack trace`。

TODO: `stack trace`

js原生的Error相关的内置对象主要有以下几种：

1.**SyntaxError: 语法错误，表示错误的原因：在解析代码的过程中发生的语法错误。比如JSON.parse()**
2.**ReferenceError: 引用错误，表示错误的原因：无效引用。**
3.**RangeError: 范围错误,表示错误的原因：数值变量或参数超出其有效范围**
4.**TypeError: 类型错误，表示错误的原因：变量或参数不属于有效类型。**
5.EvalError: eval()方法错误的使用
6.URIError: 表示错误的原因：给 encodeURI()或  decodeURl()传递的参数无效。

以上错误类型都是继承自`Error`对象。前四种是我们常遇到的异常类型。当然我们也可以根据我们自己的需要通过集成`Error`对象，实现我们自己的自定义Error对象。

#### try catch

要抛出一个异常，我们需要使用`throw` 关键字，而为了捕获一个异常，则需要用到`try catch`语法。

`try catch` 语法块
 
``` javascript
try{
  throw new Error('somthing error')
}catch(error) {
  // ...code
  .alert(error.message)
}finally{
  console.log('finally')
}

```

`try`块中是需要执行的语句，当出现异常时代码会直接中断，进入`catch`块中。在`catch`块中可以根据需要处理异常。

`finally`块并不是必选的，当有`finally`块存在时，无论是否有异常，最终代码都会进入到`finally`中并执行。一般如果有类似于需要清除的状态，或者释放资源时，我们可以用到它

如果提供了`finally`语句，那么`catch`语句就是可选的了。

```javascript

function hello() {
  const timer = startTime()

  try {
    throw new Error('Bad happen')
  } finally {
    endTime(timer)
  }
}

```

**注意：**，当`try`或者`catch`中有`return`语句时，如果`finally`中也有`return`，则`try catch` 中的`return` 会被忽略。比如下面代码，最终的返回值会是‘finally’

```javascript

function hello(){
  try{
    console.log(1)
    return 1
  } catch(error) {
    console.log(error.message)
    return 2
  } finally {
    console.log('finally')
    return 'finally'
  }
}

```

只能捕获到同步的运行时异常。

``` javascript

try{
  setTimeout(() => {
    throw new Error('timeout')
  }, 1000)
} catch (err) {
  console.log('catch error: ', err.message)
}

```



#### 防御式编程

在编程的世界中，往往会遇到大量的非法数据，在这个时候，一名合格的程序员，当然是合适的处理这些非法数据，以免自己编写的程序出现错误。奥利给！

> 异常和集成有一点是相同的：谨慎明智的使用时，可以降低代码的复杂程度；而草率粗心的使用时，只会让代码变得几乎无法理解。

那么我们如果更好的抛出和捕获异常呢？下面就来详细的说一下一些可用的技术：

1. 返回中立值

有些时候最好的处理异常的手段就是返回一个没有危害的值，例如：

```typescript

interface IElement {
  children: IElement[]
}

function hasChild(element: IElement){
  if(!element) return false

  // ...code
}

```

但是，需要注意的是，并不是所有的情况，都存在一个合适返回的中立值，例如：

```typescript
function getAverageNum(nums: number[]){
  if(!isArray(nums) || !isEveryNumbers(nums)) {
    throw new TypeError('nums have to be an array of numbers')
  }

  // ...other check
}
```

2. 只有真正例外的情况下才抛出异常

异常是一个非常强大的错误处理系统，但是我们最好不要在业务代码中去依赖他的特性去使用它，异常建议的使用情况应该用来处理预料之外的情况。

3. 具体而明确
   
具体明确是指我们抛出异常时应该针对具体的来抛出异常，而且抛出的异常应该尽可能的详细具体；在捕获时也应该尽可能的针对异常进行细分。

而且我们应该将越具体的异常放在越前面。
```typescript
function readFile(path){
  if(!isString(path)) {
    throw new TypeError('invalid Params: path is not string')
  }

  if(!fs.pathExist(path)){
    throw new Error('File not found')
  }

  // ...other check
}
```

4. 提早抛出

5. 延迟捕获

6. 不要忽略异常
 
```javascript

try {
  // 很多代码
} catch(err) {}

```

因为try代码块中所有的异常，都会被这个空的catch所捕获，从而导致所有的异常信息都会丢失掉。





